Workbook

Sheet Premissas e Resultado
A1: Viabilidade: serviço de moagem de aparas (Boituva-SP)
A2: Altere só as células AMARELAS com texto AZUL. O resto é calculado. Valores iniciais são estimativas para ponto de partida.
A4: 1. Volume e preço
A5: Capacidade da máquina (t/dia) | B5: 4 | C5: Informado pelo usuário: até 4 t/dia.
A6: Dias úteis por mês | B6: 22 | C6: Sábados extras aumentam a capacidade.
A7: Capacidade máxima (t/mês) | B7: =$B$5*$B$6 -> 88
A8: Volume contratado (t/mês) | B8: 80 | C8: Quanto os clientes mandam por mês. O contato do pai fala em 100 t/mês.
A9: Volume processado (t/mês) | B9: =MIN($B$8,$B$7) -> 80 | C9: Limitado à capacidade da máquina.
A10: Ocupação da máquina | B10: =IF($B$7>0,$B$9/$B$7,0) -> 0.90909091
A11: Preço do serviço (R$/kg) | B11: 0.8 | C11: A DEFINIR: nenhum concorrente publica. Pedir orçamentos (Nicoplas, Flex, Gedel, Alassia).
A12: Impostos sobre faturamento (%) | B12: 0.1 | C12: Estimativa (Simples Nacional, faixa inicial). Confirmar com contador.
A14: 2. Custos variáveis (por tonelada)
A15: Energia consumida (kWh/t) | B15: 100 | C15: Estimativa. Medir com a potência real dos motores do pai.
A16: Tarifa de energia (R$/kWh) | B16: 0.8 | C16: Conferir na conta de luz industrial (CPFL/Elektro).
A17: Energia (R$/t) | B17: =$B$15*$B$16 -> 80
A18: Facas e manutenção (R$/t) | B18: 40 | C18: Estimativa. Fita e filme desgastam menos que rígido.
A19: Big bags por tonelada | B19: 2 | C19: Fita picada é leve (volumosa): ~400–600 kg por bag.
A20: Preço do big bag (R$) | B20: 30 | C20: Zere se o cliente fornecer o bag.
A21: Big bags (R$/t) | B21: =$B$19*$B$20 -> 60
A22: Custo variável total (R$/t) | B22: =$B$17+$B$18+$B$21 -> 180
A24: 3. Custos fixos (por mês)
A25: Número de funcionários | B25: 4 | C25: Alimentador, operador de saída, empilhadeirista, líder.
A26: Custo por funcionário (R$/mês) | B26: 4000 | C26: Salário + encargos + benefícios. Estimativa.
A27: Mão de obra (R$/mês) | B27: =$B$25*$B$26 -> 16000
A28: Galpão (R$/mês) | B28: 10000 | C28: Zere se o galpão for próprio.
A29: Empilhadeira (R$/mês) | B29: 6000 | C29: Aluguel. Se comprar usada, zere aqui e coloque no investimento.
A30: Contador, seguro, licenças, internet etc. (R$/mês) | B30: 5000 | C30: Estimativa.
A31: Pró-labore dos sócios (R$/mês) | B31: 0 | C31: Quanto vocês dois vão tirar. Começa em zero.
A32: Custo fixo total (R$/mês) | B32: =$B$27+$B$28+$B$29+$B$30+$B$31 -> 37000
A34: 4. Investimento inicial
A35: Adequação NR-12 das máquinas (R$) | B35: 25000 | C35: Proteções, intertravamento, emergência, laudo. Estimativa: cotar.
A36: Licenças, CETESB, AVCB, abertura (R$) | B36: 15000 | C36: Estimativa: cotar com despachante/consultoria ambiental.
A37: Balança e instalação elétrica (R$) | B37: 20000 | C37: Estimativa.
A38: Capital de giro (R$) | B38: 40000 | C38: Para pagar ~2 meses de custos antes de receber.
A39: Investimento total (R$) | B39: =$B$35+$B$36+$B$37+$B$38 -> 100000 | C39: Máquinas do pai não entram (já existem).
A41: 5. Resultado mensal
A42: Faturamento bruto (R$/mês) | B42: =$B$9*1000*$B$11 -> 64000
A43: (-) Impostos (R$/mês) | B43: =$B$42*$B$12 -> 6400
A44: (-) Custos variáveis (R$/mês) | B44: =$B$9*$B$22 -> 14400
A45: (-) Custos fixos (R$/mês) | B45: =$B$32 -> 37000
...

Sheet Sensibilidade
A1: Lucro mensal (R$) por preço × volume
A2: Usa custos da aba 'Premissas e Resultado'. Vermelho = prejuízo. Volume acima da capacidade é limitado à capacidade.
A4: Volume (t/mês) ↓ Preço (R$/kg) → | B4: 0.4 | C4: 0.5 | D4: 0.6 | E4: 0.7 | F4: 0.8 | G4: 0.9 | H4: 1 | I4: 1.2
A5: 20 | B5: =MIN($A5,'Premissas e Resultado'!$B$7)*1000*B$4*(1-'Premissas e Resultado'!$B$12)-MIN($A5,'Premissas e Resultado'!$B$7)*'Premissas e Resultado'!$B$22-'Premissas e Resultado'!$B$32 -> -33400 | C5: =MIN($A5,'Premissas e Resultado'!$B$7)*1000*C$4*(1-'Premissas e Resultado'!$B$12)-MIN($A5,'Premissas e Resultado'!$B$7)*'Premissas e Resultado'!$B$22-'Premissas e Resultado'!$B$32 -> -31600 | D5: =MIN($A5,'Premissas e Resultado'!$B$7)*1000*D$4*(1-'Premissas e Resultado'!$B$12)-MIN($A5,'Premissas e Resultado'!$B$7)*'Premissas e Resultado'!$B$22-'Premissas e Resultado'!$B$32 -> -29800 | E5: =MIN($A5,'Premissas e Resultado'!$B$7)*1000*E$4*(1-'Premissas e Resultado'!$B$12)-MIN($A5,'Premissas e Resultado'!$B$7)*'Premissas e Resultado'!$B$22-'Premissas e Resultado'!$B$32 -> -28000 | F5: =MIN($A5,'Premissas e Resultado'!$B$7)*1000*F$4*(1-'Premissas e Resultado'!$B$12)-MIN($A5,'Premissas e Resultado'!$B$7)*'Premissas e Resultado'!$B$22-'Premissas e Resultado'!$B$32 -> -26200 | G5: =MIN($A5,'Premissas e Resultado'!$B$7)*1000*G$4*(1-'Premissas e Resultado'!$B$12)-MIN($A5,'Premissas e Resultado'!$B$7)*'Premissas e Resultado'!$B$22-'Premissas e Resultado'!$B$32 -> -24400 | H5: =MIN($A5,'Premissas e Resultado'!$B$7)*1000*H$4*(1-'Premissas e Resultado'!$B$12)-MIN($A5,'Premissas e Resultado'!$B$7)*'Premissas e Resultado'!$B$22-'Premissas e Resultado'!$B$32 -> -22600 | I5: =MIN($A5,'Premissas e Resultado'!$B$7)*1000*I$4*(1-'Premissas e Resultado'!$B$12)-MIN($A5,'Premissas e Resultado'!$B$7)*'Premissas e Resultado'!$B$22-'Premissas e Resultado'!$B$32 -> -19000
A6: 30 | B6: =MIN($A6,'Premissas e Resultado'!$B$7)*1000*B$4*(1-'Premissas e Resultado'!$B$12)-MIN($A6,'Premissas e Resultado'!$B$7)*'Premissas e Resultado'!$B$22-'Premissas e Resultado'!$B$32 -> -31600 | C6: =MIN($A6,'Premissas e Resultado'!$B$7)*1000*C$4*(1-'Premissas e Resultado'!$B$12)-MIN($A6,'Premissas e Resultado'!$B$7)*'Premissas e Resultado'!$B$22-'Premissas e Resultado'!$B$32 -> -28900 | D6: =MIN($A6,'Premissas e Resultado'!$B$7)*1000*D$4*(1-'Premissas e Resultado'!$B$12)-MIN($A6,'Premissas e Resultado'!$B$7)*'Premissas e Resultado'!$B$22-'Premissas e Resultado'!$B$32 -> -26200 | E6: =MIN($A6,'Premissas e Resultado'!$B$7)*1000*E$4*(1-'Premissas e Resultado'!$B$12)-MIN($A6,'Premissas e Resultado'!$B$7)*'Premissas e Resultado'!$B$22-'Premissas e Resultado'!$B$32 -> -23500 | F6: =MIN($A6,'Premissas e Resultado'!$B$7)*1000*F$4*(1-'Premissas e Resultado'!$B$12)-MIN($A6,'Premissas e Resultado'!$B$7)*'Premissas e Resultado'!$B$22-'Premissas e Resultado'!$B$32 -> -20800 | G6: =MIN($A6,'Premissas e Resultado'!$B$7)*1000*G$4*(1-'Premissas e Resultado'!$B$12)-MIN($A6,'Premissas e Resultado'!$B$7)*'Premissas e Resultado'!$B$22-'Premissas e Resultado'!$B$32 -> -18100 | H6: =MIN($A6,'Premissas e Resultado'!$B$7)*1000*H$4*(1-'Premissas e Resultado'!$B$12)-MIN($A6,'Premissas e Resultado'!$B$7)*'Premissas e Resultado'!$B$22-'Premissas e Resultado'!$B$32 -> -15400 | I6: =MIN($A6,'Premissas e Resultado'!$B$7)*1000*I$4*(1-'Premissas e Resultado'!$B$12)-MIN($A6,'Premissas e Resultado'!$B$7)*'Premissas e Resultado'!$B$22-'Premissas e Resultado'!$B$32 -> -10000
A7: 40 | B7: =MIN($A7,'Premissas e Resultado'!$B$7)*1000*B$4*(1-'Premissas e Resultado'!$B$12)-MIN($A7,'Premissas e Resultado'!$B$7)*'Premissas e Resultado'!$B$22-'Premissas e Resultado'!$B$32 -> -29800 | C7: =MIN($A7,'Premissas e Resultado'!$B$7)*1000*C$4*(1-'Premissas e Resultado'!$B$12)-MIN($A7,'Premissas e Resultado'!$B$7)*'Premissas e Resultado'!$B$22-'Premissas e Resultado'!$B$32 -> -26200 | D7: =MIN($A7,'Premissas e Resultado'!$B$7)*1000*D$4*(1-'Premissas e Resultado'!$B$12)-MIN($A7,'Premissas e Resultado'!$B$7)*'Premissas e Resultado'!$B$22-'Premissas e Resultado'!$B$32 -> -22600 | E7: =MIN($A7,'Premissas e Resultado'!$B$7)*1000*E$4*(1-'Premissas e Resultado'!$B$12)-MIN($A7,'Premissas e Resultado'!$B$7)*'Premissas e Resultado'!$B$22-'Premissas e Resultado'!$B$32 -> -19000 | F7: =MIN($A7,'Premissas e Resultado'!$B$7)*1000*F$4*(1-'Premissas e Resultado'!$B$12)-MIN($A7,'Premissas e Resultado'!$B$7)*'Premissas e Resultado'!$B$22-'Premissas e Resultado'!$B$32 -> -15400 | G7: =MIN($A7,'Premissas e Resultado'!$B$7)*1000*G$4*(1-'Premissas e Resultado'!$B$12)-MIN($A7,'Premissas e Resultado'!$B$7)*'Premissas e Resultado'!$B$22-'Premissas e Resultado'!$B$32 -> -11800 | H7: =MIN($A7,'Premissas e Resultado'!$B$7)*1000*H$4*(1-'Premissas e Resultado'!$B$12)-MIN($A7,'Premissas e Resultado'!$B$7)*'Premissas e Resultado'!$B$22-'Premissas e Resultado'!$B$32 -> -8200 | I7: =MIN($A7,'Premissas e Resultado'!$B$7)*1000*I$4*(1-'Premissas e Resultado'!$B$12)-MIN($A7,'Premissas e Resultado'!$B$7)*'Premissas e Resultado'!$B$22-'Premissas e Resultado'!$B$32 -> -1000
A8: 50 | B8: =MIN($A8,'Premissas e Resultado'!$B$7)*1000*B$4*(1-'Premissas e Resultado'!$B$12)-MIN($A8,'Premissas e Resultado'!$B$7)*'Premissas e Resultado'!$B$22-'Premissas e Resultado'!$B$32 -> -28000 | C8: =MIN($A8,'Premissas e Resultado'!$B$7)*1000*C$4*(1-'Premissas e Resultado'!$B$12)-MIN($A8,'Premissas e Resultado'!$B$7)*'Premissas e Resultado'!$B$22-'Premissas e Resultado'!$B$32 -> -23500 | D8: =MIN($A8,'Premissas e Resultado'!$B$7)*1000*D$4*(1-'Premissas e Resultado'!$B$12)-MIN($A8,'Premissas e Resultado'!$B$7)*'Premissas e Resultado'!$B$22-'Premissas e Resultado'!$B$32 -> -19000 | E8: =MIN($A8,'Premissas e Resultado'!$B$7)*1000*E$4*(1-'Premissas e Resultado'!$B$12)-MIN($A8,'Premissas e Resultado'!$B$7)*'Premissas e Resultado'!$B$22-'Premissas e Resultado'!$B$32 -> -14500 | F8: =MIN($A8,'Premissas e Resultado'!$B$7)*1000*F$4*(1-'Premissas e Resultado'!$B$12)-MIN($A8,'Premissas e Resultado'!$B$7)*'Premissas e Resultado'!$B$22-'Premissas e Resultado'!$B$32 -> -10000 | G8: =MIN($A8,'Premissas e Resultado'!$B$7)*1000*G$4*(1-'Premissas e Resultado'!$B$12)-MIN($A8,'Premissas e Resultado'!$B$7)*'Premissas e Resultado'!$B$22-'Premissas e Resultado'!$B$32 -> -5500 | H8: =MIN($A8,'Premissas e Resultado'!$B$7)*1000*H$4*(1-'Premissas e Resultado'!$B$12)-MIN($A8,'Premissas e Resultado'!$B$7)*'Premissas e Resultado'!$B$22-'Premissas e Resultado'!$B$32 -> -1000 | I8: =MIN($A8,'Premissas e Resultado'!$B$7)*1000*I$4*(1-'Premissas e Resultado'!$B$12)-MIN($A8,'Premissas e Resultado'!$B$7)*'Premissas e Resultado'!$B$22-'Premissas e Resultado'!$B$32 -> 8000
A9: 60 | B9: =MIN($A9,'Premissas e Resultado'!$B$7)*1000*B$4*(1-'Premissas e Resultado'!$B$12)-MIN($A9,'Premissas e Resultado'!$B$7)*'Premissas e Resultado'!$B$22-'Premissas e Resultado'!$B$32 -> -26200 | C9: =MIN($A9,'Premissas e Resultado'!$B$7)*1000*C$4*(1-'Premissas e Resultado'!$B$12)-MIN($A9,'Premissas e Resultado'!$B$7)*'Premissas e Resultado'!$B$22-'Premissas e Resultado'!$B$32 -> -20800 | D9: =MIN($A9,'Premissas e Resultado'!$B$7)*1000*D$4*(1-'Premissas e Resultado'!$B$12)-MIN($A9,'Premissas e Resultado'!$B$7)*'Premissas e Resultado'!$B$22-'Premissas e Resultado'!$B$32 -> -15400 | E9: =MIN($A9,'Premissas e Resultado'!$B$7)*1000*E$4*(1-'Premissas e Resultado'!$B$12)-MIN($A9,'Premissas e Resultado'!$B$7)*'Premissas e Resultado'!$B$22-'Premissas e Resultado'!$B$32 -> -10000 | F9: =MIN($A9,'Premissas e Resultado'!$B$7)*1000*F$4*(1-'Premissas e Resultado'!$B$12)-MIN($A9,'Premissas e Resultado'!$B$7)*'Premissas e Resultado'!$B$22-'Premissas e Resultado'!$B$32 -> -4600 | G9: =MIN($A9,'Premissas e Resultado'!$B$7)*1000*G$4*(1-'Premissas e Resultado'!$B$12)-MIN($A9,'Premissas e Resultado'!$B$7)*'Premissas e Resultado'!$B$22-'Premissas e Resultado'!$B$32 -> 800 | H9: =MIN($A9,'Premissas e Resultado'!$B$7)*1000*H$4*(1-'Premissas e Resultado'!$B$12)-MIN($A9,'Premissas e Resultado'!$B$7)*'Premissas e Resultado'!$B$22-'Premissas e Resultado'!$B$32 -> 6200 | I9: =MIN($A9,'Premissas e Resultado'!$B$7)*1000*I$4*(1-'Premissas e Resultado'!$B$12)-MIN($A9,'Premissas e Resultado'!$B$7)*'Premissas e Resultado'!$B$22-'Premissas e Resultado'!$B$32 -> 17000
A10: 70 | B10: =MIN($A10,'Premissas e Resultado'!$B$7)*1000*B$4*(1-'Premissas e Resultado'!$B$12)-MIN($A10,'Premissas e Resultado'!$B$7)*'Premissas e Resultado'!$B$22-'Premissas e Resultado'!$B$32 -> -24400 | C10: =MIN($A10,'Premissas e Resultado'!$B$7)*1000*C$4*(1-'Premissas e Resultado'!$B$12)-MIN($A10,'Premissas e Resultado'!$B$7)*'Premissas e Resultado'!$B$22-'Premissas e Resultado'!$B$32 -> -18100 | D10: =MIN($A10,'Premissas e Resultado'!$B$7)*1000*D$4*(1-'Premissas e Resultado'!$B$12)-MIN($A10,'Premissas e Resultado'!$B$7)*'Premissas e Resultado'!$B$22-'Premissas e Resultado'!$B$32 -> -11800 | E10: =MIN($A10,'Premissas e Resultado'!$B$7)*1000*E$4*(1-'Premissas e Resultado'!$B$12)-MIN($A10,'Premissas e Resultado'!$B$7)*'Premissas e Resultado'!$B$22-'Premissas e Resultado'!$B$32 -> -5500 | F10: =MIN($A10,'Premissas e Resultado'!$B$7)*1000*F$4*(1-'Premissas e Resultado'!$B$12)-MIN($A10,'Premissas e Resultado'!$B$7)*'Premissas e Resultado'!$B$22-'Premissas e Resultado'!$B$32 -> 800 | G10: =MIN($A10,'Premissas e Resultado'!$B$7)*1000*G$4*(1-'Premissas e Resultado'!$B$12)-MIN($A10,'Premissas e Resultado'!$B$7)*'Premissas e Resultado'!$B$22-'Premissas e Resultado'!$B$32 -> 7100 | H10: =MIN($A10,'Premissas e Resultado'!$B$7)*1000*H$4*(1-'Premissas e Resultado'!$B$12)-MIN($A10,'Premissas e Resultado'!$B$7)*'Premissas e Resultado'!$B$22-'Premissas e Resultado'!$B$32 -> 13400 | I10: =MIN($A10,'Premissas e Resultado'!$B$7)*1000*I$4*(1-'Premissas e Resultado'!$B$12)-MIN($A10,'Premissas e Resultado'!$B$7)*'Premissas e Resultado'!$B$22-'Premissas e Resultado'!$B$32 -> 26000
A11: 80 | B11: =MIN($A11,'Premissas e Resultado'!$B$7)*1000*B$4*(1-'Premissas e Resultado'!$B$12)-MIN($A11,'Premissas e Resultado'!$B$7)*'Premissas e Resultado'!$B$22-'Premissas e Resultado'!$B$32 -> -22600 | C11: =MIN($A11,'Premissas e Resultado'!$B$7)*1000*C$4*(1-'Premissas e Resultado'!$B$12)-MIN($A11,'Premissas e Resultado'!$B$7)*'Premissas e Resultado'!$B$22-'Premissas e Resultado'!$B$32 -> -15400 | D11: =MIN($A11,'Premissas e Resultado'!$B$7)*1000*D$4*(1-'Premissas e Resultado'!$B$12)-MIN($A11,'Premissas e Resultado'!$B$7)*'Premissas e Resultado'!$B$22-'Premissas e Resultado'!$B$32 -> -8200 | E11: =MIN($A11,'Premissas e Resultado'!$B$7)*1000*E$4*(1-'Premissas e Resultado'!$B$12)-MIN($A11,'Premissas e Resultado'!$B$7)*'Premissas e Resultado'!$B$22-'Premissas e Resultado'!$B$32 -> -1000 | F11: =MIN($A11,'Premissas e Resultado'!$B$7)*1000*F$4*(1-'Premissas e Resultado'!$B$12)-MIN($A11,'Premissas e Resultado'!$B$7)*'Premissas e Resultado'!$B$22-'Premissas e Resultado'!$B$32 -> 6200 | G11: =MIN($A11,'Premissas e Resultado'!$B$7)*1000*G$4*(1-'Premissas e Resultado'!$B$12)-MIN($A11,'Premissas e Resultado'!$B$7)*'Premissas e Resultado'!$B$22-'Premissas e Resultado'!$B$32 -> 13400 | H11: =MIN($A11,'Premissas e Resultado'!$B$7)*1000*H$4*(1-'Premissas e Resultado'!$B$12)-MIN($A11,'Premissas e Resultado'!$B$7)*'Premissas e Resultado'!$B$22-'Premissas e Resultado'!$B$32 -> 20600 | I11: =MIN($A11,'Premissas e Resultado'!$B$7)*1000*I$4*(1-'Premissas e Resultado'!$B$12)-MIN($A11,'Premissas e Resultado'!$B$7)*'Premissas e Resultado'!$B$22-'Premissas e Resultado'!$B$32 -> 35000
A12: 88 | B12: =MIN($A12,'Premissas e Resultado'!$B$7)*1000*B$4*(1-'Premissas e Resultado'!$B$12)-MIN($A12,'Premissas e Resultado'!$B$7)*'Premissas e Resultado'!$B$22-'Premissas e Resultado'!$B$32 -> -21160 | C12: =MIN($A12,'Premissas e Resultado'!$B$7)*1000*C$4*(1-'Premissas e Resultado'!$B$12)-MIN($A12,'Premissas e Resultado'!$B$7)*'Premissas e Resultado'!$B$22-'Premissas e Resultado'!$B$32 -> -13240 | D12: =MIN($A12,'Premissas e Resultado'!$B$7)*1000*D$4*(1-'Premissas e Resultado'!$B$12)-MIN($A12,'Premissas e Resultado'!$B$7)*'Premissas e Resultado'!$B$22-'Premissas e Resultado'!$B$32 -> -5320 | E12: =MIN($A12,'Premissas e Resultado'!$B$7)*1000*E$4*(1-'Premissas e Resultado'!$B$12)-MIN($A12,'Premissas e Resultado'!$B$7)*'Premissas e Resultado'!$B$22-'Premissas e Resultado'!$B$32 -> 2600 | F12: =MIN($A12,'Premissas e Resultado'!$B$7)*1000*F$4*(1-'Premissas e Resultado'!$B$12)-MIN($A12,'Premissas e Resultado'!$B$7)*'Premissas e Resultado'!$B$22-'Premissas e Resultado'!$B$32 -> 10520 | G12: =MIN($A12,'Premissas e Resultado'!$B$7)*1000*G$4*(1-'Premissas e Resultado'!$B$12)-MIN($A12,'Premissas e Resultado'!$B$7)*'Premissas e Resultado'!$B$22-'Premissas e Resultado'!$B$32 -> 18440 | H12: =MIN($A12,'Premissas e Resultado'!$B$7)*1000*H$4*(1-'Premissas e Resultado'!$B$12)-MIN($A12,'Premissas e Resultado'!$B$7)*'Premissas e Resultado'!$B$22-'Premissas e Resultado'!$B$32 -> 26360 | I12: =MIN($A12,'Premissas e Resultado'!$B$7)*1000*I$4*(1-'Premissas e Resultado'!$B$12)-MIN($A12,'Premissas e Resultado'!$B$7)*'Premissas e Resultado'!$B$22-'Premissas e Resultado'!$B$32 -> 42200
A13: 100 | B13: =MIN($A13,'Premissas e Resultado'!$B$7)*1000*B$4*(1-'Premissas e Resultado'!$B$12)-MIN($A13,'Premissas e Resultado'!$B$7)*'Premissas e Resultado'!$B$22-'Premissas e Resultado'!$B$32 -> -21160 | C13: =MIN($A13,'Premissas e Resultado'!$B$7)*1000*C$4*(1-'Premissas e Resultado'!$B$12)-MIN($A13,'Premissas e Resultado'!$B$7)*'Premissas e Resultado'!$B$22-'Premissas e Resultado'!$B$32 -> -13240 | D13: =MIN($A13,'Premissas e Resultado'!$B$7)*1000*D$4*(1-'Premissas e Resultado'!$B$12)-MIN($A13,'Premissas e Resultado'!$B$7)*'Premissas e Resultado'!$B$22-'Premissas e Resultado'!$B$32 -> -5320 | E13: =MIN($A13,'Premissas e Resultado'!$B$7)*1000*E$4*(1-'Premissas e Resultado'!$B$12)-MIN($A13,'Premissas e Resultado'!$B$7)*'Premissas e Resultado'!$B$22-'Premissas e Resultado'!$B$32 -> 2600 | F13: =MIN($A13,'Premissas e Resultado'!$B$7)*1000*F$4*(1-'Premissas e Resultado'!$B$12)-MIN($A13,'Premissas e Resultado'!$B$7)*'Premissas e Resultado'!$B$22-'Premissas e Resultado'!$B$32 -> 10520 | G13: =MIN($A13,'Premissas e Resultado'!$B$7)*1000*G$4*(1-'Premissas e Resultado'!$B$12)-MIN($A13,'Premissas e Resultado'!$B$7)*'Premissas e Resultado'!$B$22-'Premissas e Resultado'!$B$32 -> 18440 | H13: =MIN($A13,'Premissas e Resultado'!$B$7)*1000*H$4*(1-'Premissas e Resultado'!$B$12)-MIN($A13,'Premissas e Resultado'!$B$7)*'Premissas e Resultado'!$B$22-'Premissas e Resultado'!$B$32 -> 26360 | I13: =MIN($A13,'Premissas e Resultado'!$B$7)*1000*I$4*(1-'Premissas e Resultado'!$B$12)-MIN($A13,'Premissas e Resultado'!$B$7)*'Premissas e Resultado'!$B$22-'Premissas e Resultado'!$B$32 -> 42200

Sheet 12 meses
A1: Projeção de 12 meses (ano de prestação de serviço)
A2: Linha amarela = volume esperado em cada mês (rampa de clientes). Preço e custos vêm da aba de premissas.
A4: Mês | B4: 1 | C4: 2 | D4: 3 | E4: 4 | F4: 5 | G4: 6 | H4: 7 | I4: 8 | J4: 9 | K4: 10 | L4: 11 | M4: 12
A5: Volume (t/mês) | B5: 30 | C5: 45 | D5: 60 | E5: 70 | F5: 80 | G5: 80 | H5: 85 | I5: 88 | J5: 88 | K5: 88 | L5: 88 | M5: 88
A6: Volume processado (t) | B6: =MIN(B5,'Premissas e Resultado'!$B$7) -> 30 | C6: =MIN(C5,'Premissas e Resultado'!$B$7) -> 45 | D6: =MIN(D5,'Premissas e Resultado'!$B$7) -> 60 | E6: =MIN(E5,'Premissas e Resultado'!$B$7) -> 70 | F6: =MIN(F5,'Premissas e Resultado'!$B$7) -> 80 | G6: =MIN(G5,'Premissas e Resultado'!$B$7) -> 80 | H6: =MIN(H5,'Premissas e Resultado'!$B$7) -> 85 | I6: =MIN(I5,'Premissas e Resultado'!$B$7) -> 88 | ... M6: =MIN(M5,'Premissas e Resultado'!$B$7) -> 88
A7: Faturamento (R$) | B7: =B6*1000*'Premissas e Resultado'!$B$11 -> 24000 | C7: =C6*1000*'Premissas e Resultado'!$B$11 -> 36000 | D7: =D6*1000*'Premissas e Resultado'!$B$11 -> 48000 | E7: =E6*1000*'Premissas e Resultado'!$B$11 -> 56000 | F7: =F6*1000*'Premissas e Resultado'!$B$11 -> 64000 | G7: =G6*1000*'Premissas e Resultado'!$B$11 -> 64000 | H7: =H6*1000*'Premissas e Resultado'!$B$11 -> 68000 | I7: =I6*1000*'Premissas e Resultado'!$B$11 -> 70400 | ... M7: =M6*1000*'Premissas e Resultado'!$B$11 -> 70400
A8: (-) Impostos | B8: =-B7*'Premissas e Resultado'!$B$12 -> -2400 | C8: =-C7*'Premissas e Resultado'!$B$12 -> -3600 | D8: =-D7*'Premissas e Resultado'!$B$12 -> -4800 | E8: =-E7*'Premissas e Resultado'!$B$12 -> -5600 | F8: =-F7*'Premissas e Resultado'!$B$12 -> -6400 | G8: =-G7*'Premissas e Resultado'!$B$12 -> -6400 | H8: =-H7*'Premissas e Resultado'!$B$12 -> -6800 | I8: =-I7*'Premissas e Resultado'!$B$12 -> -7040 | ... M8: =-M7*'Premissas e Resultado'!$B$12 -> -7040
A9: (-) Variáveis | B9: =-B6*'Premissas e Resultado'!$B$22 -> -5400 | C9: =-C6*'Premissas e Resultado'!$B$22 -> -8100 | D9: =-D6*'Premissas e Resultado'!$B$22 -> -10800 | E9: =-E6*'Premissas e Resultado'!$B$22 -> -12600 | F9: =-F6*'Premissas e Resultado'!$B$22 -> -14400 | G9: =-G6*'Premissas e Resultado'!$B$22 -> -14400 | H9: =-H6*'Premissas e Resultado'!$B$22 -> -15300 | I9: =-I6*'Premissas e Resultado'!$B$22 -> -15840 | ... M9: =-M6*'Premissas e Resultado'!$B$22 -> -15840
A10: (-) Fixos | B10: =-'Premissas e Resultado'!$B$32 -> -37000 | C10: =-'Premissas e Resultado'!$B$32 -> -37000 | D10: =-'Premissas e Resultado'!$B$32 -> -37000 | E10: =-'Premissas e Resultado'!$B$32 -> -37000 | F10: =-'Premissas e Resultado'!$B$32 -> -37000 | G10: =-'Premissas e Resultado'!$B$32 -> -37000 | H10: =-'Premissas e Resultado'!$B$32 -> -37000 | I10: =-'Premissas e Resultado'!$B$32 -> -37000 | ... M10: =-'Premissas e Resultado'!$B$32 -> -37000
A11: Lucro do mês (R$) | B11: =SUM(B7:B10) -> -20800 | C11: =SUM(C7:C10) -> -12700 | D11: =SUM(D7:D10) -> -4600 | E11: =SUM(E7:E10) -> 800 | F11: =SUM(F7:F10) -> 6200 | G11: =SUM(G7:G10) -> 6200 | H11: =SUM(H7:H10) -> 8900 | I11: =SUM(I7:I10) -> 10520 | ... M11: =SUM(M7:M10) -> 10520
A12: Caixa acumulado (R$) | B12: =-'Premissas e Resultado'!$B$39+B11 -> -120800 | C12: =B12+C11 -> -133500 | D12: =C12+D11 -> -138100 | E12: =D12+E11 -> -137300 | F12: =E12+F11 -> -131100 | G12: =F12+G11 -> -124900 | H12: =G12+H11 -> -116000 | I12: =H12+I11 -> -105480 | J12: =I12+J11 -> -94960 | ... M12: =L12+M11 -> -63400
A14: Total do ano | B14: =SUM(B11:M11) -> 36600
